<?xml version="1.0" ?>
<!-- =================================================================================== -->
<!-- |    This document was autogenerated by xacro from /home/ashwin/catkin_ws/src/cartf/urdf/my_robot_integration.urdf.xacro | -->
<!-- |    EDITING THIS FILE BY HAND IS NOT RECOMMENDED                                 | -->
<!-- =================================================================================== -->
<!-- Name your robot here -->
<robot name="cartf" xmlns:xacro="http://wiki.ros.org/xacro">
  <link name="dummy_link">
  </link>
  <joint name="dummy_joint" type="fixed">
    <parent link="dummy_link"/>
    <child link="chasis"/>
  </joint>
  <link name="chasis">
    <inertial>
      <origin rpy="0 0 0" xyz="0.306715325013249 -2.71753020976429E-06 -0.00815667635088907"/>
      <mass value="33.2144018580194"/>
      <inertia ixx="0.956231733187828" ixy="2.11975354628092E-06" ixz="0.11287715356547" iyy="1.47602928869039" iyz="-4.42219326557769E-06" izz="1.78987781011623"/>
    </inertial>
    <visual>
      <origin rpy="0 0 0" xyz="0 0 0"/>
      <geometry>
        <mesh filename="package://cartf/meshes/chasis.STL"/>
      </geometry>
      <material name="">
        <color rgba="0.792156862745098 0.819607843137255 0.933333333333333 1"/>
      </material>
    </visual>
    <collision>
      <origin rpy="0 0 0" xyz="0 0 0"/>
      <geometry>
        <mesh filename="package://cartf/meshes/chasis.STL"/>
      </geometry>
    </collision>
  </link>
  <link name="rr_spindle">
    <inertial>
      <origin rpy="0 0 0" xyz="-2.77555756156289E-17 -0.0206015076592078 1.11022302462516E-16"/>
      <mass value="0.032963329762829"/>
      <inertia ixx="3.15195491740579E-05" ixy="-1.99865146250362E-20" ixz="-2.99046320933935E-22" iyy="5.29773895211035E-06" iyz="3.53680736486934E-22" izz="3.29550665766564E-05"/>
    </inertial>
    <visual>
      <origin rpy="0 0 0" xyz="0 0 0"/>
      <geometry>
        <mesh filename="package://cartf/meshes/rr_spindle.STL"/>
      </geometry>
      <material name="">
        <color rgba="0.792156862745098 0.819607843137255 0.933333333333333 1"/>
      </material>
    </visual>
    <collision>
      <origin rpy="0 0 0" xyz="0 0 0"/>
      <geometry>
        <mesh filename="package://cartf/meshes/rr_spindle.STL"/>
      </geometry>
    </collision>
  </link>
  <joint name="rrs_joint" type="fixed">
    <origin rpy="1.5707963267949 0 -1.5707963267949" xyz="0.5461 0.200455304230583 -0.05715"/>
    <parent link="chasis"/>
    <child link="rr_spindle"/>
    <axis xyz="0 0 0"/>
  </joint>
  <link name="rr_wheel">
    <inertial>
      <origin rpy="0 0 0" xyz="-1.11022302462516E-16 -1.38777878078145E-17 0"/>
      <mass value="0.125423442065565"/>
      <inertia ixx="0.000120072398611804" ixy="-1.91230954179958E-23" ixz="3.81164826264435E-21" iyy="0.000237185353944132" iyz="-5.33287966975338E-22" izz="0.000120072398611804"/>
    </inertial>
    <visual>
      <origin rpy="0 0 0" xyz="0 0 0"/>
      <geometry>
        <mesh filename="package://cartf/meshes/rr_wheel.STL"/>
      </geometry>
      <material name="">
        <color rgba="0.792156862745098 0.819607843137255 0.933333333333333 1"/>
      </material>
    </visual>
    <collision>
      <origin rpy="0 0 0" xyz="0 0 0"/>
      <geometry>
        <mesh filename="package://cartf/meshes/rr_wheel.STL"/>
      </geometry>
    </collision>
  </link>
  <joint name="rrw_joint" type="fixed">
    <origin rpy="3.14159265358979 1.54340479703384 1.5707963267949" xyz="0 -0.08509 0"/>
    <parent link="rr_spindle"/>
    <child link="rr_wheel"/>
    <axis xyz="0 0 0"/>
  </joint>
  <link name="rl_spindle">
    <inertial>
      <origin rpy="0 0 0" xyz="0 -0.0396515076592077 1.11022302462516E-16"/>
      <mass value="0.0329633297628291"/>
      <inertia ixx="3.15195491740579E-05" ixy="-6.98098857709146E-20" ixz="3.47008933615623E-22" iyy="5.29773895211036E-06" iyz="-1.29829194023181E-22" izz="3.29550665766565E-05"/>
    </inertial>
    <visual>
      <origin rpy="0 0 0" xyz="0 0 0"/>
      <geometry>
        <mesh filename="package://cartf/meshes/rl_spindle.STL"/>
      </geometry>
      <material name="">
        <color rgba="0.792156862745098 0.819607843137255 0.933333333333333 1"/>
      </material>
    </visual>
    <collision>
      <origin rpy="0 0 0" xyz="0 0 0"/>
      <geometry>
        <mesh filename="package://cartf/meshes/rl_spindle.STL"/>
      </geometry>
    </collision>
  </link>
  <joint name="rls_joint" type="continuous">
    <origin rpy="1.5707963267949 0 -1.5707963267949" xyz="0.5461 -0.198324695769416 -0.0381"/>
    <parent link="chasis"/>
    <child link="rl_spindle"/>
    <axis xyz="0 1 0"/>
  </joint>
  <link name="rl_wheel">
    <inertial>
      <origin rpy="0 0 0" xyz="-0.00148279198290668 5.55111512312578E-17 0.0541196907597912"/>
      <mass value="0.125423442065565"/>
      <inertia ixx="0.000120072398611804" ixy="-2.9583421033843E-23" ixz="3.81164826264435E-21" iyy="0.000237185353944132" iyz="-3.63860835099325E-22" izz="0.000120072398611804"/>
    </inertial>
    <visual>
      <origin rpy="0 0 0" xyz="0 0 0"/>
      <geometry>
        <mesh filename="package://cartf/meshes/rl_wheel.STL"/>
      </geometry>
      <material name="">
        <color rgba="0.792156862745098 0.819607843137255 0.933333333333333 1"/>
      </material>
    </visual>
    <collision>
      <origin rpy="0 0 0" xyz="0 0 0"/>
      <geometry>
        <mesh filename="package://cartf/meshes/rl_wheel.STL"/>
      </geometry>
    </collision>
  </link>
  <joint name="rlw_joint" type="continuous">
    <origin rpy="3.14159265358979 1.54340479703384 1.5707963267949" xyz="0 -0.05 0"/>
    <parent link="rl_spindle"/>
    <child link="rl_wheel"/>
    <axis xyz="0.0273881045974643 0 -0.999624875504085"/>
  </joint>
  <link name="fr_spindle">
    <inertial>
      <origin rpy="0 0 0" xyz="1.52655665885959E-16 -0.0396515076592076 8.88178419700125E-16"/>
      <mass value="0.0329633297628289"/>
      <inertia ixx="3.15195491740577E-05" ixy="-3.26037767873418E-21" ixz="1.05879118406788E-20" iyy="5.29773895211029E-06" iyz="-6.4567825328811E-21" izz="3.29550665766563E-05"/>
    </inertial>
    <visual>
      <origin rpy="0 0 0" xyz="0 0 0"/>
      <geometry>
        <mesh filename="package://cartf/meshes/fr_spindle.STL"/>
      </geometry>
      <material name="">
        <color rgba="0.792156862745098 0.819607843137255 0.933333333333333 1"/>
      </material>
    </visual>
    <collision>
      <origin rpy="0 0 0" xyz="0 0 0"/>
      <geometry>
        <mesh filename="package://cartf/meshes/fr_spindle.STL"/>
      </geometry>
    </collision>
  </link>
  <joint name="frs_joint" type="continuous">
    <origin rpy="1.5707963267949 0 -1.79506698933366" xyz="0.1143 0.200662394443895 -0.0380999999999998"/>
    <parent link="chasis"/>
    <child link="fr_spindle"/>
    <axis xyz="0 1 0"/>
  </joint>
  <link name="fr_wheel">
    <inertial>
      <origin rpy="0 0 0" xyz="-0.00148279198290791 1.2490009027033E-16 0.0541196907597912"/>
      <mass value="0.125423442065565"/>
      <inertia ixx="0.000120072398611804" ixy="6.82708555486966E-19" ixz="6.35274710440725E-21" iyy="0.000237185353944132" iyz="5.72806030580721E-20" izz="0.000120072398611804"/>
    </inertial>
    <visual>
      <origin rpy="0 0 0" xyz="0 0 0"/>
      <geometry>
        <mesh filename="package://cartf/meshes/fr_wheel.STL"/>
      </geometry>
      <material name="">
        <color rgba="0.792156862745098 0.819607843137255 0.933333333333333 1"/>
      </material>
    </visual>
    <collision>
      <origin rpy="0 0 0" xyz="0 0 0"/>
      <geometry>
        <mesh filename="package://cartf/meshes/fr_wheel.STL"/>
      </geometry>
    </collision>
  </link>
  <joint name="frw_joint" type="continuous">
    <origin rpy="3.14159265358979 1.54340479703383 1.5707963267949" xyz="0 -0.05 0"/>
    <parent link="fr_spindle"/>
    <child link="fr_wheel"/>
    <axis xyz="0.02738810459747 0 -0.999624875504085"/>
  </joint>
  <link name="fl_spindle">
    <inertial>
      <origin rpy="0 0 0" xyz="2.22044604925031E-16 -0.0396515076592077 -5.55111512312578E-17"/>
      <mass value="0.032963329762829"/>
      <inertia ixx="3.15195491740578E-05" ixy="-1.19324752228375E-20" ixz="1.6940658945086E-21" iyy="5.29773895211036E-06" iyz="1.72142061655695E-21" izz="3.29550665766563E-05"/>
    </inertial>
    <visual>
      <origin rpy="0 0 0" xyz="0 0 0"/>
      <geometry>
        <mesh filename="package://cartf/meshes/fl_spindle.STL"/>
      </geometry>
      <material name="">
        <color rgba="0.792156862745098 0.819607843137255 0.933333333333333 1"/>
      </material>
    </visual>
    <collision>
      <origin rpy="0 0 0" xyz="0 0 0"/>
      <geometry>
        <mesh filename="package://cartf/meshes/fl_spindle.STL"/>
      </geometry>
    </collision>
  </link>
  <joint name="fls_joint" type="continuous">
    <origin rpy="1.5707963267949 0 -2.72589179740421" xyz="0.1143 -0.198324695769416 -0.0381"/>
    <parent link="chasis"/>
    <child link="fl_spindle"/>
    <axis xyz="0 1 0"/>
  </joint>
  <link name="fl_wheel">
    <inertial>
      <origin rpy="0 0 0" xyz="-0.00148279198290707 6.66133814775094E-16 0.054119690759791"/>
      <mass value="0.125423442065566"/>
      <inertia ixx="0.000120072398611805" ixy="2.5410988417629E-19" ixz="1.16467030247466E-21" iyy="0.000237185353944134" iyz="7.72917564369549E-21" izz="0.000120072398611805"/>
    </inertial>
    <visual>
      <origin rpy="0 0 0" xyz="0 0 0"/>
      <geometry>
        <mesh filename="package://cartf/meshes/fl_wheel.STL"/>
      </geometry>
      <material name="">
        <color rgba="0.792156862745098 0.819607843137255 0.933333333333333 1"/>
      </material>
    </visual>
    <collision>
      <origin rpy="0 0 0" xyz="0 0 0"/>
      <geometry>
        <mesh filename="package://cartf/meshes/fl_wheel.STL"/>
      </geometry>
    </collision>
  </link>
  <joint name="flw_joint" type="continuous">
    <origin rpy="3.14159265358979 1.54340479703384 1.5707963267949" xyz="0 -0.05 0"/>
    <parent link="fl_spindle"/>
    <child link="fl_wheel"/>
    <axis xyz="0.02738810459747 0 -0.999624875504085"/>
  </joint>
  <transmission name="steer_right">
    <type>transmission_interface/SimpleTransmission</type>
    <joint name="frs_joint">
      <hardwareInterface>hardware_interface/EffortJointInterface</hardwareInterface>
    </joint>
    <actuator name="r_steer">
      <!--hardwareInterface>hardware_interface/EffortJointInterface</hardwareInterface-->
      <mechanicalReduction>2</mechanicalReduction>
    </actuator>
  </transmission>
  <transmission name="steer_left">
    <type>transmission_interface/SimpleTransmission</type>
    <joint name="fls_joint">
      <hardwareInterface>hardware_interface/EffortJointInterface</hardwareInterface>
    </joint>
    <actuator name="l_steer">
      <!--hardwareInterface>hardware_interface/EffortJointInterface</hardwareInterface-->
      <mechanicalReduction>2</mechanicalReduction>
    </actuator>
  </transmission>
  <transmission name="rear_right">
    <type>transmission_interface/SimpleTransmission</type>
    <joint name="rrs_joint">
      <hardwareInterface>hardware_interface/VelocityJointInterface</hardwareInterface>
    </joint>
    <actuator name="rr_wheel">
      <!--hardwareInterface>hardware_interface/VelocityJointInterface</hardwareInterface-->
      <mechanicalReduction>2</mechanicalReduction>
    </actuator>
  </transmission>
  <transmission name="rear_left">
    <type>transmission_interface/SimpleTransmission</type>
    <joint name="rls_joint">
      <hardwareInterface>hardware_interface/VelocityJointInterface</hardwareInterface>
    </joint>
    <actuator name="rl_wheel">
      <!--hardwareInterface>hardware_interface/VelocityJointInterface</hardwareInterface-->
      <mechanicalReduction>2</mechanicalReduction>
    </actuator>
  </transmission>
  <!-- Link0 -->
  <gazebo reference="base_link">
    <material>Gazebo/Grey</material>
    <mu1>2</mu1>
    <mu2>2</mu2>
  </gazebo>
  <!-- Link1 -->
  <gazebo reference="link_1">
    <mu1>0.2</mu1>
    <mu2>0.2</mu2>
  </gazebo>
  <!-- Link2 -->
  <gazebo reference="link_2">
    <mu1>0.2</mu1>
    <mu2>0.2</mu2>
  </gazebo>
  <!-- Link3 -->
  <gazebo reference="link_3">
    <mu1>0.2</mu1>
    <mu2>0.2</mu2>
  </gazebo>
  <!-- Link4 -->
  <gazebo reference="link_4">
    <mu1>0.2</mu1>
    <mu2>0.2</mu2>
  </gazebo>
  <!-- Link5 -->
  <gazebo reference="link_5">
    <mu1>0.2</mu1>
    <mu2>0.2</mu2>
  </gazebo>
  <!-- Link6 -->
  <gazebo reference="link_6">
    <mu1>0.2</mu1>
    <mu2>0.2</mu2>
  </gazebo>
  <!-- Gripper -->
  <gazebo reference="gripper_link">
    <material>Gazebo/Grey</material>
    <mu1>0.2</mu1>
    <mu2>0.2</mu2>
  </gazebo>
  <gazebo reference="left_gripper_finger_link">
    <material>Gazebo/Grey</material>
    <kp>1000000.0</kp>
    <kd>1.0</kd>
    <mu1>30.0</mu1>
    <mu2>30.0</mu2>
  </gazebo>
  <gazebo reference="right_gripper_finger_link">
    <material>Gazebo/Grey</material>
    <kp>1000000.0</kp>
    <kd>1.0</kd>
    <mu1>30.0</mu1>
    <mu2>30.0</mu2>
  </gazebo>
  <!-- ros_control plugin -->
  <gazebo>
    <plugin filename="libgazebo_ros_control.so" name="gazebo_ros_control">
      <robotNamespace>/kuka_arm</robotNamespace>
      <robotSimType>gazebo_ros_control/DefaultRobotHWSim</robotSimType>
    </plugin>
  </gazebo>
  <!-- grasp plugin -->
  <gazebo>
    <plugin filename="libgazebo_grasp_fix.so" name="gazebo_grasp_fix">
      <arm>
        <arm_name>kuka_arm</arm_name>
        <palm_link>link_6</palm_link>
        <gripper_link>right_gripper_finger_link</gripper_link>
        <gripper_link>left_gripper_finger_link</gripper_link>
      </arm>
      <forces_angle_tolerance>100</forces_angle_tolerance>
      <update_rate>4</update_rate>
      <grip_count_threshold>4</grip_count_threshold>
      <max_grip_count>8</max_grip_count>
      <release_tolerance>0.003</release_tolerance>
      <disable_collisions_on_attach>false</disable_collisions_on_attach>
      <contact_topic>__default_topic__</contact_topic>
    </plugin>
  </gazebo>
  <!--Links-->
  <link name="base_footprint"/>
  <link name="base_link">
    <inertial>
      <origin rpy="0 0 0" xyz="0 0 0"/>
      <mass value="150"/>
      <inertia ixx="60" ixy="0" ixz="0" iyy="70" iyz="0" izz="100"/>
    </inertial>
    <visual>
      <origin rpy="-1.570796327 0 0" xyz="0 0 0"/>
      <geometry>
        <mesh filename="package://kuka_arm/meshes/kr210l150/visual/base_link.dae"/>
      </geometry>
      <material name="">
        <color rgba="0.75294 0.75294 0.75294 1"/>
      </material>
    </visual>
    <collision>
      <origin rpy="-1.570796327 0 0" xyz="0 0 0"/>
      <geometry>
        <mesh filename="package://kuka_arm/meshes/kr210l150/collision/base_link.stl"/>
      </geometry>
    </collision>
  </link>
  <link name="link_1">
    <inertial>
      <origin rpy="0 0 0" xyz="0 0 0.4"/>
      <mass value="138"/>
      <inertia ixx="30" ixy="0" ixz="0" iyy="50" iyz="0" izz="50"/>
    </inertial>
    <visual>
      <origin rpy="0 0 0" xyz="0 0 0"/>
      <geometry>
        <mesh filename="package://kuka_arm/meshes/kr210l150/visual/link_1.dae"/>
      </geometry>
      <material name="">
        <color rgba="0.75294 0.75294 0.75294 1"/>
      </material>
    </visual>
    <collision>
      <origin rpy="0 0 0" xyz="0 0 0"/>
      <geometry>
        <mesh filename="package://kuka_arm/meshes/kr210l150/collision/link_1.stl"/>
      </geometry>
    </collision>
  </link>
  <link name="link_2">
    <inertial>
      <origin rpy="0 0 0" xyz="0 0 0.44751"/>
      <mass value="95"/>
      <inertia ixx="40" ixy="0" ixz="0" iyy="40" iyz="0" izz="10"/>
    </inertial>
    <visual>
      <origin rpy="-1.570796327 0 0" xyz="0 0 0"/>
      <geometry>
        <mesh filename="package://kuka_arm/meshes/kr210l150/visual/link_2.dae"/>
      </geometry>
      <material name="">
        <color rgba="0.75294 0.75294 0.75294 1"/>
      </material>
    </visual>
    <collision>
      <origin rpy="0 0 0" xyz="0 0 0"/>
      <geometry>
        <mesh filename="package://kuka_arm/meshes/kr210l150/collision/link_2.stl"/>
      </geometry>
    </collision>
  </link>
  <link name="link_3">
    <inertial>
      <origin rpy="0 0 0" xyz="0.18842 0.18344 -0.042799"/>
      <mass value="71"/>
      <inertia ixx="1" ixy="0" ixz="0" iyy="10" iyz="0" izz="10"/>
    </inertial>
    <visual>
      <origin rpy="-1.570796327 0 0" xyz="0 -0.184 0"/>
      <geometry>
        <mesh filename="package://kuka_arm/meshes/kr210l150/visual/link_3.dae"/>
      </geometry>
      <material name="">
        <color rgba="0.75294 0.75294 0.75294 1"/>
      </material>
    </visual>
    <collision>
      <origin rpy="0 0 0" xyz="0 -0.184 0"/>
      <geometry>
        <mesh filename="package://kuka_arm/meshes/kr210l150/collision/link_3.stl"/>
      </geometry>
    </collision>
  </link>
  <link name="link_4">
    <inertial>
      <origin rpy="0 0 0" xyz="0.27146 -0.007326 0"/>
      <mass value="17"/>
      <inertia ixx="0.18" ixy="0" ixz="0" iyy="0.55" iyz="0" izz="0.64"/>
    </inertial>
    <visual>
      <origin rpy="-1.570796327 0 0" xyz="0 0 0"/>
      <geometry>
        <mesh filename="package://kuka_arm/meshes/kr210l150/visual/link_4.dae"/>
      </geometry>
      <material name="">
        <color rgba="0.75294 0.75294 0.75294 1"/>
      </material>
    </visual>
    <collision>
      <origin rpy="0 0 0" xyz="0 0 0"/>
      <geometry>
        <mesh filename="package://kuka_arm/meshes/kr210l150/collision/link_4.stl"/>
      </geometry>
    </collision>
  </link>
  <link name="link_5">
    <inertial>
      <origin rpy="0 0 0" xyz="0 0 0"/>
      <mass value="7"/>
      <inertia ixx="0.04" ixy="0" ixz="0" iyy="0.068" iyz="0" izz="0.068"/>
    </inertial>
    <visual>
      <origin rpy="-1.570796327 0 0" xyz="0 0 0"/>
      <geometry>
        <mesh filename="package://kuka_arm/meshes/kr210l150/visual/link_5.dae"/>
      </geometry>
      <material name="">
        <color rgba="0.75294 0.75294 0.75294 1"/>
      </material>
    </visual>
    <collision>
      <origin rpy="0 0 0" xyz="0 0 0"/>
      <geometry>
        <mesh filename="package://kuka_arm/meshes/kr210l150/collision/link_5.stl"/>
      </geometry>
    </collision>
  </link>
  <link name="link_6">
    <inertial>
      <origin rpy="0 0 0" xyz="0 0 0"/>
      <mass value="0.5"/>
      <inertia ixx="0.004" ixy="0" ixz="0" iyy="0.003" iyz="0" izz="0.003"/>
    </inertial>
    <visual>
      <origin rpy="0 0 0" xyz="0 0 0"/>
      <geometry>
        <mesh filename="package://kuka_arm/meshes/kr210l150/visual/link_6.dae"/>
      </geometry>
      <material name="">
        <color rgba="0.75294 0.75294 0.75294 1"/>
      </material>
    </visual>
    <collision>
      <origin rpy="0 0 0" xyz="0 0 0"/>
      <geometry>
        <mesh filename="package://kuka_arm/meshes/kr210l150/collision/link_6.stl"/>
      </geometry>
    </collision>
  </link>
  <link name="gripper_link">
    <inertial>
      <origin rpy="0 0 0" xyz="0 0 0"/>
      <mass value="0.3"/>
      <inertia ixx="0.0001" ixy="0" ixz="0" iyy="0.0002" iyz="0" izz="0.0001"/>
    </inertial>
    <visual>
      <origin rpy="0 0 0" xyz="0 0 0"/>
      <geometry>
        <mesh filename="package://kuka_arm/meshes/gripper/gripper_base.dae"/>
      </geometry>
    </visual>
    <collision>
      <origin rpy="0 0 0" xyz="0 0 0"/>
      <geometry>
        <mesh filename="package://kuka_arm/meshes/gripper/gripper_base.dae"/>
      </geometry>
    </collision>
  </link>
  <link name="right_gripper_finger_link">
    <inertial>
      <origin rpy="0 0 0" xyz="0 0 0"/>
      <mass value="0.1"/>
      <inertia ixx="0.002" ixy="0" ixz="0" iyy="0.0002" iyz="0" izz="0.0002"/>
    </inertial>
    <visual>
      <origin rpy="0 0 0" xyz="0 0 0"/>
      <geometry>
        <mesh filename="package://kuka_arm/meshes/gripper/finger_right.dae"/>
      </geometry>
    </visual>
    <collision>
      <origin rpy="0 0 0" xyz="0 0 0"/>
      <geometry>
        <mesh filename="package://kuka_arm/meshes/gripper/finger_right_collision.dae"/>
      </geometry>
    </collision>
  </link>
  <link name="left_gripper_finger_link">
    <inertial>
      <origin rpy="0 0 0" xyz="0 0 0"/>
      <mass value="0.1"/>
      <inertia ixx="0.002" ixy="0" ixz="0" iyy="0.0002" iyz="0" izz="0.0002"/>
    </inertial>
    <visual>
      <origin rpy="0 0 0" xyz="0 0 0"/>
      <geometry>
        <mesh filename="package://kuka_arm/meshes/gripper/finger_left.dae"/>
      </geometry>
    </visual>
    <collision>
      <origin rpy="0 0 0" xyz="0 0 0"/>
      <geometry>
        <mesh filename="package://kuka_arm/meshes/gripper/finger_left_collision.dae"/>
      </geometry>
    </collision>
  </link>
  <joint name="right_gripper_finger_joint" type="prismatic">
    <origin rpy="0 0 0" xyz="0.15 -0.0725 0"/>
    <parent link="gripper_link"/>
    <child link="right_gripper_finger_link"/>
    <axis xyz="0 1 0"/>
    <limit effort="100" lower="-0.01" upper="0.06" velocity="0.05"/>
    <dynamics damping="0.7"/>
  </joint>
  <joint name="left_gripper_finger_joint" type="prismatic">
    <origin rpy="0 0 0" xyz="0.15 0.0725 0"/>
    <parent link="gripper_link"/>
    <child link="left_gripper_finger_link"/>
    <axis xyz="0 -1 0"/>
    <limit effort="100" lower="-0.01" upper="0.06" velocity="0.05"/>
    <dynamics damping="0.7"/>
  </joint>
  <joint name="gripper_joint" type="fixed">
    <parent link="link_6"/>
    <child link="gripper_link"/>
    <origin rpy="0 0 0" xyz="0.11 0 0"/>
    <!--0.087-->
    <axis xyz="0 1 0"/>
  </joint>
  <transmission name="tran7">
    <type>transmission_interface/SimpleTransmission</type>
    <joint name="left_gripper_finger_joint">
      <hardwareInterface>hardware_interface/EffortJointInterface</hardwareInterface>
    </joint>
    <actuator name="motor7">
      <hardwareInterface>hardware_interface/EffortJointInterface</hardwareInterface>
      <mechanicalReduction>1</mechanicalReduction>
    </actuator>
  </transmission>
  <transmission name="tran8">
    <type>transmission_interface/SimpleTransmission</type>
    <joint name="right_gripper_finger_joint">
      <hardwareInterface>hardware_interface/EffortJointInterface</hardwareInterface>
    </joint>
    <actuator name="motor8">
      <hardwareInterface>hardware_interface/EffortJointInterface</hardwareInterface>
      <mechanicalReduction>1</mechanicalReduction>
    </actuator>
  </transmission>
  <!-- joints -->
  <joint name="fixed_base_joint" type="fixed">
    <parent link="base_footprint"/>
    <child link="base_link"/>
    <origin rpy="0 0 0" xyz="0 0 0"/>
  </joint>
  <joint name="joint_1" type="revolute">
    <origin rpy="0 0 0" xyz="0 0 0.33"/>
    <parent link="base_link"/>
    <child link="link_1"/>
    <axis xyz="0 0 1"/>
    <limit effort="300" lower="-3.228859205" upper="3.228859205" velocity="2.146755039"/>
  </joint>
  <joint name="joint_2" type="revolute">
    <origin rpy="0 0 0" xyz="0.35 0 0.42"/>
    <parent link="link_1"/>
    <child link="link_2"/>
    <axis xyz="0 1 0"/>
    <limit effort="300" lower="-0.785398185" upper="1.483529905" velocity="2.007128695"/>
  </joint>
  <joint name="joint_3" type="revolute">
    <origin rpy="0 0 0" xyz="0 0 1.25"/>
    <parent link="link_2"/>
    <child link="link_3"/>
    <axis xyz="0 1 0"/>
    <limit effort="300" lower="-3.66519153" upper="1.134464045" velocity="1.954768816"/>
  </joint>
  <joint name="joint_4" type="revolute">
    <origin rpy="0 0 0" xyz="0.96 0 -0.054"/>
    <parent link="link_3"/>
    <child link="link_4"/>
    <axis xyz="1 0 0"/>
    <limit effort="300" lower="-6.10865255" upper="6.10865255" velocity="3.124139447"/>
  </joint>
  <joint name="joint_5" type="revolute">
    <origin rpy="0 0 0" xyz="0.54 0 0"/>
    <parent link="link_4"/>
    <child link="link_5"/>
    <axis xyz="0 1 0"/>
    <limit effort="300" lower="-2.181661625" upper="2.181661625" velocity="3.001966396"/>
  </joint>
  <joint name="joint_6" type="revolute">
    <origin rpy="0 0 0" xyz="0.193 0 0"/>
    <parent link="link_5"/>
    <child link="link_6"/>
    <axis xyz="1 0 0"/>
    <limit effort="300" lower="-6.10865255" upper="6.10865255" velocity="3.822271167"/>
  </joint>
  <!--Transmission and actuators-->
  <transmission name="tran1">
    <type>transmission_interface/SimpleTransmission</type>
    <joint name="joint_1">
      <hardwareInterface>hardware_interface/PositionJointInterface</hardwareInterface>
    </joint>
    <actuator name="motor1">
      <hardwareInterface>hardware_interface/PositionJointInterface</hardwareInterface>
      <mechanicalReduction>1</mechanicalReduction>
    </actuator>
  </transmission>
  <transmission name="tran2">
    <type>transmission_interface/SimpleTransmission</type>
    <joint name="joint_2">
      <hardwareInterface>hardware_interface/PositionJointInterface</hardwareInterface>
    </joint>
    <actuator name="motor2">
      <hardwareInterface>hardware_interface/PositionJointInterface</hardwareInterface>
      <mechanicalReduction>1</mechanicalReduction>
    </actuator>
  </transmission>
  <transmission name="tran3">
    <type>transmission_interface/SimpleTransmission</type>
    <joint name="joint_3">
      <hardwareInterface>hardware_interface/PositionJointInterface</hardwareInterface>
    </joint>
    <actuator name="motor3">
      <hardwareInterface>hardware_interface/PositionJointInterface</hardwareInterface>
      <mechanicalReduction>1</mechanicalReduction>
    </actuator>
  </transmission>
  <transmission name="tran4">
    <type>transmission_interface/SimpleTransmission</type>
    <joint name="joint_4">
      <hardwareInterface>hardware_interface/PositionJointInterface</hardwareInterface>
    </joint>
    <actuator name="motor4">
      <hardwareInterface>hardware_interface/PositionJointInterface</hardwareInterface>
      <mechanicalReduction>1</mechanicalReduction>
    </actuator>
  </transmission>
  <transmission name="tran5">
    <type>transmission_interface/SimpleTransmission</type>
    <joint name="joint_5">
      <hardwareInterface>hardware_interface/PositionJointInterface</hardwareInterface>
    </joint>
    <actuator name="motor5">
      <hardwareInterface>hardware_interface/PositionJointInterface</hardwareInterface>
      <mechanicalReduction>1</mechanicalReduction>
    </actuator>
  </transmission>
  <transmission name="tran6">
    <type>transmission_interface/SimpleTransmission</type>
    <joint name="joint_6">
      <hardwareInterface>hardware_interface/PositionJointInterface</hardwareInterface>
    </joint>
    <actuator name="motor6">
      <hardwareInterface>hardware_interface/PositionJointInterface</hardwareInterface>
      <mechanicalReduction>1</mechanicalReduction>
    </actuator>
  </transmission>
  <!-- Add your gazebo sensors here -->
  <gazebo reference="base_laser">
    <!-- <gravity>true</gravity> -->
    <!-- Gazebo has fixed set of Sensors types. Check them out here <> -->
    <sensor name="laser" type="ray">
      <!-- Add in your sensor characteristics -->
      <pose> 0 0 0 0 0 0 </pose>
      <visualise>true</visualise>
      <update_rate>40</update_rate>
      <!-- <always_on>true</always_on> -->
      <ray>
        <scan>
          <horizontal>
            <samples>720</samples>
            <resolution>1</resolution>
            <min_angle>-1.570796</min_angle>
            <max_angle>1.570796</max_angle>
          </horizontal>
        </scan>
        <range>
          <min>0.10</min>
          <max>30.0</max>
          <resolution>0.01</resolution>
        </range>
        <noise>
          <type>gaussian</type>
          <mean>0.0</mean>
          <stddev>0.01</stddev>
        </noise>
      </ray>
      <plugin filename="libgazebo_ros_laser.so" name="gazebo_ros_head_hokuyo_controller">
        <!-- Use topic name as /my_robot/scan -->
        <topicName>toy_carf/scan</topicName>
        <frameName>laser_frame</frameName>
      </plugin>
    </sensor>
  </gazebo>
  <!--  Gazebo plugin for control here is already added for you -->
  <gazebo>
    <plugin filename="libgazebo_ros_control.so" name="gazebo_ros_control">
      <robotNamespace>/cartf</robotNamespace>
      <robotSimType>gazebo_ros_control/DefaultRobotHWSim</robotSimType>
      <legacyModeNS>true</legacyModeNS>
    </plugin>
  </gazebo>
  <!-- Create a joint between your robot and sensor -->
  <joint name="robot_arm" type="fixed">
    <origin rpy="0 0 1.75" xyz="0 0.475 0"/>
    <parent link="chasis"/>
    <child link="base_footprint"/>
  </joint>
</robot>
